<?xml version="1.0"?>
<robot name="picar">
  <link name="base_link">
    <visual>
      <geometry><box size="0.26 0.17 0.06"/></geometry>
      <material name="gray"><color rgba="0.7 0.7 0.7 1"/></material>
    </visual>
    <collision>
      <geometry><box size="0.26 0.17 0.06"/></geometry>
    </collision>
    <inertial>
      <mass value="1.8"/>
      <inertia ixx="0.08" ixy="0" ixz="0" iyy="0.08" iyz="0" izz="0.08"/>
    </inertial>
  </link>
  <link name="wheel_fl">
    <visual>
      <geometry><cylinder length="0.03" radius="0.032"/></geometry>
      <origin rpy="1.5707 0 0" xyz="0 0 0"/>
      <material name="white"><color rgba="1 1 1 1"/></material>
    </visual>
    <collision>
      <geometry><cylinder length="0.03" radius="0.032"/></geometry>
      <origin rpy="1.5707 0 0" xyz="0 0 0"/>
    </collision>
    <inertial>
      <mass value="0.05"/>
      <inertia ixx="0.001" ixy="0" ixz="0" iyy="0.001" iyz="0" izz="0.001"/>
    </inertial>
  </link>
  <joint name="joint_fl" type="continuous">
    <parent link="base_link"/>
    <child link="wheel_fl"/>
    <origin xyz="0.13 0.085 -0.032"/>
    <axis xyz="0 1 0"/>
    <limit effort="20.0" velocity="30.0"/>
  </joint>
  <link name="wheel_fr">
    <visual>
      <geometry><cylinder length="0.03" radius="0.032"/></geometry>
      <origin rpy="1.5707 0 0" xyz="0 0 0"/>
      <material name="white"><color rgba="1 1 1 1"/></material>
    </visual>
    <collision>
      <geometry><cylinder length="0.03" radius="0.032"/></geometry>
      <origin rpy="1.5707 0 0" xyz="0 0 0"/>
    </collision>
    <inertial>
      <mass value="0.05"/>
      <inertia ixx="0.001" ixy="0" ixz="0" iyy="0.001" iyz="0" izz="0.001"/>
    </inertial>
  </link>
  <joint name="joint_fr" type="continuous">
    <parent link="base_link"/>
    <child link="wheel_fr"/>
    <origin xyz="0.13 -0.085 -0.032"/>
    <axis xyz="0 1 0"/>
    <limit effort="20.0" velocity="30.0"/>
  </joint>
  <link name="wheel_rl">
    <visual>
      <geometry><cylinder length="0.04" radius="0.035"/></geometry>
      <origin rpy="1.5707 0 0" xyz="0 0 0"/>
      <material name="black"><color rgba="0.1 0.1 0.1 1"/></material>
    </visual>
    <collision>
      <geometry><cylinder length="0.04" radius="0.035"/></geometry>
      <origin rpy="1.5707 0 0" xyz="0 0 0"/>
    </collision>
    <inertial>
      <mass value="0.12"/>
      <inertia ixx="0.002" ixy="0" ixz="0" iyy="0.002" iyz="0" izz="0.002"/>
    </inertial>
  </link>
  <joint name="joint_rl" type="continuous">
    <parent link="base_link"/>
    <child link="wheel_rl"/>
    <origin xyz="-0.13 0.085 -0.035"/>
    <axis xyz="0 1 0"/>
    <limit effort="20.0" velocity="30.0"/>
  </joint>
  <link name="wheel_rr">
    <visual>
      <geometry><cylinder length="0.04" radius="0.035"/></geometry>
      <origin rpy="1.5707 0 0" xyz="0 0 0"/>
      <material name="black"><color rgba="0.1 0.1 0.1 1"/></material>
    </visual>
    <collision>
      <geometry><cylinder length="0.04" radius="0.035"/></geometry>
      <origin rpy="1.5707 0 0" xyz="0 0 0"/>
    </collision>
    <inertial>
      <mass value="0.12"/>
      <inertia ixx="0.002" ixy="0" ixz="0" iyy="0.002" iyz="0" izz="0.002"/>
    </inertial>
  </link>
  <joint name="joint_rr" type="continuous">
    <parent link="base_link"/>
    <child link="wheel_rr"/>
    <origin xyz="-0.13 -0.085 -0.035"/>
    <axis xyz="0 1 0"/>
    <limit effort="20.0" velocity="30.0"/>
  </joint>
  <link name="camera_link">
    <visual>
      <geometry><box size="0.04 0.06 0.04"/></geometry>
      <origin xyz="0 0 0" rpy="0 0 0"/>
      <material name="black"><color rgba="0.2 0.2 0.2 1"/></material>
    </visual>
    <collision>
      <geometry><box size="0.04 0.06 0.04"/></geometry>
    </collision>
    <inertial>
      <mass value="0.05"/>
      <inertia ixx="0.0001" ixy="0" ixz="0" iyy="0.0001" iyz="0" izz="0.0001"/>
    </inertial>
  </link>
  <joint name="camera_joint" type="fixed">
    <parent link="base_link"/>
    <child link="camera_link"/>
    <origin xyz="0.14 0 0.10" rpy="0 0 0"/>
  </joint>
</robot>